Workbook

Sheet Main
B3: Scrum Project
B4: Product | C4: SmartRegression AI
B5: Active versions | C5: MVP v1.0 planned
B7: Team | E7: Product Owner | F7: Jan Samuelsson
B8: Scrum Master | C8: Nguyen Tan Huy | E8: Other Stakeholders | F8: Jan Samuelsson - Project Mentor
B9: Developers | C9: Nguyen Tan Huy | F9: Developers and QA Engineers | G9: Sprint | H9: Start | I9: End | J9: Status | K9: Work planned (Committed) | L9: Work spent (Delivered) | M9: Remarks
C10: Do Ha An | G10: 1 | H10: Week 1 | I10: Week 3 | J10: Planned | M10: Research foundation + technical spike
C11: Pham Phan Hoang Huy | G11: 2 | H11: Week 4 | I11: Week 6 | J11: Planned | K11: ='Sprint 2 Backlog'!G38 -> 232 | M11: Proposed plan; see Sprint 2 Reports.
C12: Tran Hung Khanh | G12: 3 | H12: Week 7 | I12: Week 9 | J12: Planned | M12: LLM-assisted test selection + fallback + pilot execution
C13: Dang Dai Viet | G13: 4 | H13: Week 10 | I13: Week 12 | J13: Planned | M13: CI/CD + baselines + evaluation + finalization
B18: Projects | H18: Sprint Plan | J18: Project #1
B19: Id | C19: Description | D19: Start | E19: End | F19: Status | H19: Sprint | I19: Start | J19: End | K19: Status | L19: Work planned (Committed) | M19: Work spent (Delivered) | N19: Remarks
B20: SR-AI-01 | C20: SmartRegression AI MVP | D20: 46257 | E20: 46369 | F20: In planning | H20: 1 | K20: Planned | L20: 194 | N20: Research foundation and technical spike
H21: 2 | K21: Planned | L21: ='Sprint 2 Backlog'!G38 -> 232 | N21: Proposed 232 task hours; reserve 32h; resource need 264h. Actual capacity pending. PostgreSQL accepted by user; see Sprint 2 Reports.
H22: 3 | I22: =J21+3 -> 3 | J22: =I22+11 -> 14 | K22: Planned | N22: LLM-assisted selection and dataset preparation
H23: 4 | I23: =J22+3 -> 17 | J23: =I23+11 -> 28 | K23: Planned | N23: Full evaluation and project finalization
I24: =J23+3 -> 31 | J24: =I24+11 -> 42

Sheet Product Backlog
B5: Product Backlog aligned to Proposal v1.4. Planning estimates are Scrum estimates; research outcomes are not pre-claimed.
B7: Id | C7: Heading | D7: As a.. | E7: I want to .. | F7: so that .. | G7: Acceptance Criteria | H7: Remarks | I7: Priority | J7: Status | K7: Type | L7: Project Id | M7: Sprint No | N7: Estimate (Hours) | O7: Effort (Actual) | P7: Owner | Q7: Status | R7: Remarks
B8: PB01 | C8: Connect authorized GitHub repository | D8: Maintainer | E8: connect an authorized GitHub repository | F8: the system can access the selected project safely | G8: Accept valid authorized repository; show identity/status; reject unauthorized access | H8: FR-01 | I8: 1 | J8: Proposed | K8: Feature | L8: SmartRegression AI | M8: 1 | N8: 15 | O8: Nguyen Tan Huy | R8: Initial estimate
B9: PB02 | C9: Configure testing environment | D9: Maintainer | E9: configure one supported test framework, locations, command, timeout and resource limits | F9: analysis can be executed under controlled rules | G9: Validate required settings; reject invalid command or non-positive limits; persist configuration | H9: FR-02 | I9: 1 | J9: Proposed | K9: Feature | L9: SmartRegression AI | M9: 1 | N9: 15 | O9: Tran Hung Khanh | R9: Initial estimate
B10: PB03 | C10: Select and freeze change range | D10: Developer | E10: select two commits or a pull request | F10: the exact base and target SHAs are fixed for the run | G10: Resolve base/target SHAs; show changed files; freeze SHAs; new PR head creates a separate run | H10: FR-03 | I10: 1 | J10: Proposed | K10: Feature | L10: SmartRegression AI | M10: 1 | N10: 20 | O10: Do Ha An | R10: Initial estimate Sprint 2 proposed: 2.15 snapshot prerequisite. PB scope/estimate retained; task hours differ.
B11: PB04 | C11: Start and monitor analysis | D11: Developer | E11: start an analysis run | F11: I can track the run from queue to terminal status | G11: Create run ID; show stage/timestamps/status; retain actionable failure reason; prevent duplicate integration jobs | H11: FR-04 | I11: 1 | J11: Proposed | K11: Feature | L11: SmartRegression AI | M11: 1 | N11: 15 | O11: Nguyen Tan Huy | R11: Initial estimate Sprint 2 proposed: 2.13/2.14; 2.20 foundation support. PB scope/estimate retained; task hours differ.
B12: PB05 | C12: Review code changes | D12: Developer | E12: review changed files/functions/classes/modules and diffs | F12: I can understand what changed | G12: Display diffs and source locations resolving at the analyzed version | H12: FR-05 | I12: 1 | J12: Proposed | K12: Feature | L12: SmartRegression AI | M12: 2 | N12: 25 | O12: Do Ha An | R12: Initial estimate Sprint 2 proposed: 2.01/2.02; 2.14/2.15/2.18 support. PB scope/estimate retained; task hours differ.
B13: PB06 | C13: Compute potential impact | D13: Developer | E13: see directly and indirectly affected components | F13: I can identify possible impact areas | G13: Compute supported dependency paths; distinguish changed vs potentially affected components; disclose unsupported cases | H13: FR-06 | I13: 1 | J13: Proposed | K13: Feature | L13: SmartRegression AI | M13: 2 | N13: 35 | O13: Pham Phan Hoang Huy | R13: Initial estimate Sprint 2 proposed: 2.03–2.05; 2.14/2.16/2.17/2.20 support. PB scope/estimate retained; task hours differ.
B14: PB07 | C14: Inspect impact evidence | D14: Developer | E14: inspect evidence behind impact explanations | F14: I can verify the analysis | G14: Link source locations, commit references and dependency evidence; mark invalid references unverified | H14: FR-07 | I14: 1 | J14: Proposed | K14: Feature | L14: SmartRegression AI | M14: 2 | N14: 25 | O14: Pham Phan Hoang Huy | R14: Refine in Sprint 2 Sprint 2 proposed: 2.06; 2.14/2.17/2.18 support. PB scope/estimate retained; task hours differ.
B15: PB08 | C15: Find review starting points | D15: Developer | E15: receive ordered review starting points | F15: I know where to begin manual review | G15: Order changed executable, direct dependents, indirect dependents; stable tie-breaking; no calibrated fault-probability claim | H15: FR-08 | I15: 2 | J15: Proposed | K15: Feature | L15: SmartRegression AI | M15: 2 | N15: 20 | O15: Dang Dai Viet | R15: Refine in Sprint 2 Sprint 2 proposed: 2.07. PB scope/estimate retained; task hours differ.
B16: PB09 | C16: Discover existing target tests | D16: QA Engineer | E16: view the existing target-version tests | F16: only real existing tests enter the selection inventory | G16: Stable test identifiers and source locations; distinguish empty inventory from discovery failure; record adapter/version | H16: FR-09 | I16: 1 | J16: Proposed | K16: Feature | L16: SmartRegression AI | M16: 2 | N16: 25 | O16: Tran Hung Khanh | R16: Refine in Sprint 2 Sprint 2 proposed: 2.08/2.09; 2.14/2.16/2.17/2.20 support. PB scope/estimate retained; task hours differ.
B17: PB10 | C17: Generate and validate selection manifest | D17: QA Engineer | E17: receive a validated test-selection manifest | F17: only valid existing tests can be dispatched | G17: Target SHA; selected/not-selected groups; counts; reasons; fallback mode; groups partition inventory; no invented IDs | H17: FR-10 | I17: 1 | J17: Proposed | K17: Feature | L17: SmartRegression AI | M17: 3 | N17: 30 | O17: Tran Hung Khanh | R17: Refine in Sprint 3
B18: PB11 | C18: Explain test-selection reasons | D18: QA Engineer | E18: inspect reasons for selected and not-selected tests | F18: I can verify each decision | G18: Provide source evidence/dependency path/rule per decision or group; never claim not-selected proves no regression detection | H18: FR-11 | I18: 1 | J18: Proposed | K18: Feature | L18: SmartRegression AI | M18: 3 | N18: 30 | O18: Pham Phan Hoang Huy | R18: Refine in Sprint 3
B19: PB12 | C19: Apply fallback policy | D19: QA Engineer | E19: receive a conservative fallback when analysis is incomplete | F19: test-reduction risk is controlled | G19: Record trigger and final mode; support dependency+modified set, full-suite fallback, or explicit stop according to proposal rules | H19: FR-12 | I19: 1 | J19: Proposed | K19: Safety | L19: SmartRegression AI | M19: 3 | N19: 30 | O19: Tran Hung Khanh | R19: Refine in Sprint 3
... B24: PB17 | C24: Integrate one CI/CD platform | D24: DevOps Engineer | E24: trigger analysis from commit/PR events | F24: the workflow can run experimentally in CI/CD | G24: One platform; return status/outcome/report links; duplicate events idempotent; failures never become passing; full-suite fallback explicitly marked | H24: FR-17 | I24: 2 | J24: Proposed | K24: Integration | L24: SmartRegression AI | M24: 4 | N24: 30 | O24: Tran Hung Khanh | R24: Initial estimate
B25: PB18 | C25: Run predefined evaluation methods | D25: Researcher / Evaluator | E25: run predefined datasets and supported methods | F25: I can compare the proposed method with baselines | G25: Compare full suite, dependency-based selection, LLM-based selection and SmartRegression AI; N/A for missing labels/zero denominators | H25: FR-18 | I25: 1 | J25: Proposed | K25: Research | L25: SmartRegression AI | M25: 4 | N25: 35 | O25: Dang Dai Viet
B26: PB19 | C26: Build RAG project index | D26: Researcher | E26: index source code, tests and documentation | F26: project-specific context can be retrieved for LLM analysis | G26: Index by repository and commit; preserve path/revision metadata; exclude secrets and evaluation labels | H26: Design: RAG | I26: 1 | J26: Proposed | K26: Research | L26: SmartRegression AI | M26: 2 | N26: 35 | O26: Pham Phan Hoang Huy | R26: Sprint 2 proposed: 2.10; 2.14/2.15/2.20 support. PB scope/estimate retained; task hours differ.
B27: PB20 | C27: Retrieve change-relevant context | D27: System | E27: retrieve source/tests/docs related to changed and candidate components | F27: the LLM receives focused project context | G27: Queries derived from diff/candidates; ranked results with metadata; record insufficient retrieval | H27: Design: RAG | I27: 1 | J27: Proposed | K27: Feature | L27: SmartRegression AI | M27: 2 | N27: 30 | O27: Pham Phan Hoang Huy | R27: Sprint 2 proposed: 2.11/2.12; 2.14/2.17/2.20 support. PB scope/estimate retained; task hours differ.
B28: PB21 | C28: Validate LLM output | D28: System | E28: validate LLM proposals before selection/execution | F28: LLM output cannot bypass system safety rules | G28: Validate schema, inventory membership and commit-linked evidence; never interpret LLM output as executable shell commands | H28: Design: LLM | I28: 1 | J28: Proposed | K28: Safety | L28: SmartRegression AI | M28: 3 | N28: 30 | O28: Pham Phan Hoang Huy
B29: PB22 | C29: Implement selection policy | D29: System | E29: combine dependency-selected, modified and valid LLM-added tests | F29: selection is conservative and reproducible | G29: S=(D∪M∪L)∩T; LLM may add but not remove D/M; persist T\S, evidence and policy version | H29: Design: Selection Policy | I29: 1 | J29: Proposed | K29: Research | L29: SmartRegression AI | M29: 3 | N29: 25 | O29: Tran Hung Khanh | R29: Sprint 2 proposed: 2.16 prepares mapping only; Sprint 3 assignment retained. PB scope/estimate retained; task hours differ.
B30: PB23 | C30: Prepare reproducible evaluation dataset | D30: Researcher | E30: prepare repository versions, commit pairs, labels and known defects | F30: evaluation can be repeated and audited | G30: Target ≥2 repositories, ≥30 commit pairs, ≥15 verified fault-bearing cases; separate real and mutation faults; document limitations | H30: Objective 3 | I30: 1 | J30: Proposed | K30: Research | L30: SmartRegression AI | M30: 1 | N30: 30 | O30: Dang Dai Viet
B31: PB24 | C31: Evaluate metrics and baselines | D31: Researcher | E31: calculate defined research metrics | F31: I can judge effectiveness and trade-offs | G31: Impact Precision/Recall; Evidence Accuracy; Test Reduction Rate; Fault Detection Retention; Missed Fault Rate; E2E Time Reduction; LLM Cost/Token Usage; Fallback Rate | H31: Objective 3 | I31: 1 | J31: Proposed | K31: Research | L31: SmartRegression AI | M31: 4 | N31: 40 | O31: Nguyen Tan Huy

Sheet Sprint 1 Backlog
H2: Completed is ALWAYS the estimated (planned) number of hours. You NEVER put in the number of hours you worked.
K3: Compare your estimate with the actual number of hours you spent on the task, your effort - = Spent less time than estimated | L3: Only update one time. When task is done. You update with the estimate hours, NOT the hours you actually worked to finish the task.
E4: Add Owner when task is set to Ongoing | G4: Make new estimate when move from PB to SB | I4: Remaining work to be done. | J4: Total number of hours you spent on the task. Your effort
B5: Sprint Backlog | F5: Update status during sprint
B7: Sprint Id | C7: Backlog Id | D7: Description | E7: Owner | F7: Status | G7: Estimate (Hours) | H7: Completed | I7: Pending | J7: Total effort | K7: Effort vs. Estimate | L7: Day 1 | M7: Day 2 | N7: Day 3 | O7: Day 4 | P7: Day 5 | Q7: Day 6 | R7: Day 7 | S7: Day 8 | T7: Day 9 | U7: Day 10 | V7: Day 11 | W7: Day 12 | X7: Day 13 | Y7: Day 14 | Z7: Day 15
B8: 1.01 | C8: PB23 | D8: Define research questions, baselines and metric formulas | E8: Nguyen Tan Huy | F8: Not started | G8: 10 | H8: =SUM(L8:Z8) -> 0 | I8: =G8-H8 -> 10 | J8: 0 | K8: =IF(F8="Done",J8-G8,"")
B9: 1.02 | C9: PB23 | D9: Define repository screening and evaluation criteria | E9: Dang Dai Viet | F9: Not started | G9: 8 | H9: =SUM(L9:Z9) -> 0 | I9: =G9-H9 -> 8 | J9: 0 | K9: =IF(F9="Done",J9-G9,"")
B10: 1.03 | C10: PB01 | D10: Select primary and backup repositories for the technical spike | E10: Dang Dai Viet | F10: Not started | G10: 8 | H10: =SUM(L10:Z10) -> 0 | I10: =G10-H10 -> 8 | J10: 0 | K10: =IF(F10="Done",J10-G10,"")
B11: 1.04 | C11: PB01 | D11: Prototype authorized GitHub repository connection and access validation | E11: Nguyen Tan Huy | F11: Not started | G11: 12 | H11: =SUM(L11:Z11) -> 0 | I11: =G11-H11 -> 12 | J11: 0 | K11: =IF(F11="Done",J11-G11,"")
B12: 1.05 | C12: PB02 | D12: Define supported test framework configuration and execution constraints | E12: Tran Hung Khanh | F12: Not started | G12: 8 | H12: =SUM(L12:Z12) -> 0 | I12: =G12-H12 -> 8 | J12: 0 | K12: =IF(F12="Done",J12-G12,"")
B13: 1.06 | C13: PB03 | D13: Define base/target revision and PR SHA-freezing rules | E13: Do Ha An | F13: Not started | G13: 8 | H13: =SUM(L13:Z13) -> 0 | I13: =G13-H13 -> 8 | J13: 0 | K13: =IF(F13="Done",J13-G13,"")
B14: 1.07 | C14: PB03 | D14: Prototype Git diff extraction and changed-file metadata | E14: Do Ha An | F14: Not started | G14: 14 | H14: =SUM(L14:Z14) -> 0 | I14: =G14-H14 -> 14 | J14: 0 | K14: =IF(F14="Done",J14-G14,"")
B15: 1.08 | C15: PB04 | D15: Prototype analysis run ID/status lifecycle and failure states | E15: Nguyen Tan Huy | F15: Not started | G15: 8 | H15: =SUM(L15:Z15) -> 0 | I15: =G15-H15 -> 8 | J15: 0 | K15: =IF(F15="Done",J15-G15,"")
B16: 1.09 | C16: PB19 | D16: Define RAG indexing scope, metadata and secret-exclusion rules | E16: Pham Phan Hoang Huy | F16: Not started | G16: 10 | H16: =SUM(L16:Z16) -> 0 | I16: =G16-H16 -> 10 | J16: 0 | K16: =IF(F16="Done",J16-G16,"")
B17: 1.10 | C17: PB22 | D17: Define selection/fallback policy and safety boundaries | E17: Tran Hung Khanh | F17: Not started | G17: 10 | H17: =SUM(L17:Z17) -> 0 | I17: =G17-H17 -> 10 | J17: 0 | K17: =IF(F17="Done",J17-G17,"")
B18: 1.11 | C18: PB24 | D18: Define evaluation protocol and reporting template | E18: Nguyen Tan Huy | F18: Not started | G18: 8 | H18: =SUM(L18:Z18) -> 0 | I18: =G18-H18 -> 8 | J18: 0 | K18: =IF(F18="Done",J18-G18,"")
B19: 1.12 | C19: PB23 | D19: Document technical-spike findings and Sprint 1 review/demo | E19: Nguyen Tan Huy | F19: Not started | G19: 8 | H19: =SUM(L19:Z19) -> 0 | I19: =G19-H19 -> 8 | J19: 0 | K19: =IF(F19="Done",J19-G19,"")
F38: Total | G38: =SUM(G8:G19) -> 112 | H38: =SUM(H8:H19) -> 0 | I38: =SUM(I8:I19) -> 112 | J38: =SUM(J8:J19) -> 0 | K38: =SUM(K8:K19) -> 0 | L38: =SUM(L8:L19) -> 0 | M38: =SUM(M8:M19) -> 0 | N38: =SUM(N8:N19) -> 0 | ... Z38: =SUM(Z8:Z19) -> 0
F39: Burn down | L39: =G38-L38 -> 112 | M39: =L39-M38 -> 112 | N39: =M39-N38 -> 112 | O39: =N39-O38 -> 112 | P39: =O39-P38 -> 112 | Q39: =P39-Q38 -> 112 | R39: =Q39-R38 -> 112 | S39: =R39-S38 -> 112 | T39: =S39-T38 -> 112 | ... Z39: =Y39-Z38 -> 112
F40: Burn up | L40: =L38 -> 0 | M40: =L40+M38 -> 0 | N40: =M40+N38 -> 0 | O40: =N40+O38 -> 0 | P40: =O40+P38 -> 0 | Q40: =P40+Q38 -> 0 | R40: =Q40+R38 -> 0 | S40: =R40+S38 -> 0 | T40: =S40+T38 -> 0 | ... Z40: =Y40+Z38 -> 0
J44: Worked hours/Day | L44: 1 | M44: 2 | N44: 3 | O44: 4 | P44: 5 | Q44: 6 | R44: 7 | S44: 8 | T44: 9 | U44: 10 | V44: 11 | W44: 12 | X44: 13 | Y44: 14 | Z44: 15 | AA44: Total hours
J45: Nguyen Tan Huy | AA45: =SUM(L45:Z45) -> 0
J46: Do Ha An | AA46: =SUM(L46:Z46) -> 0
J47: Pham Phan Hoang Huy | AA47: =SUM(L47:Z47) -> 0
J48: Tran Hung Khanh | AA48: =SUM(L48:Z48) -> 0
J49: Dang Dai Viet | AA49: =SUM(L49:Z49) -> 0
AA50: =SUM(AA45:AA49) -> 0
J51: Update actual worked hours per team member each day. Keep effort logs separate from planned task estimates.

Sheet Sprint 1 Reports
B5: Sprint 1 Reports & Dashboards
B7: Sprint goal: Research foundation + technical spike
B8: Record burn-down/burn-up, sprint review evidence, achieved acceptance checks and key decisions. | K8: Burn up Chart

Sheet Sprint 2 Backlog
H2: Completed is ALWAYS the estimated (planned) number of hours. You NEVER put in the number of hours you worked.
K3: Compare your estimate with the actual number of hours you spent on the task, your effort - = Spent less time than estimated | L3: Only update one time. When task is done. You update with the estimate hours, NOT the hours you actually worked to finish the task.
E4: Add Owner when task is set to Ongoing | G4: Make new estimate when move from PB to SB | I4: Remaining work to be done. | J4: Total number of hours you spent on the task. Your effort
B5: Sprint Backlog | F5: Update status during sprint
B7: Sprint Id | C7: Backlog Id | D7: Description | E7: Owner | F7: Status | G7: Estimate (Hours) | H7: Completed | I7: Pending | J7: Total effort | K7: Effort vs. Estimate | L7: Day 1 | M7: Day 2 | N7: Day 3 | O7: Day 4 | P7: Day 5 | Q7: Day 6 | R7: Day 7 | S7: Day 8 | T7: Day 9 | U7: Day 10 | V7: Day 11 | W7: Day 12 | X7: Day 13 | Y7: Day 14 | Z7: Day 15
B8: 2.01 | C8: PB05 | D8: Identify changed files, functions, classes and modules | E8: Do Ha An | F8: Not started | G8: 20 | H8: =SUM(L8:Z8) -> 0 | I8: =G8-H8 -> 20 | J8: 0 | K8: =IF(F8="Done",J8-G8,"")
B9: 2.02 | C9: PB05 | D9: Validate changed-component locations independently | E9: Dang Dai Viet | F9: Not started | G9: 8 | H9: =SUM(L9:Z9) -> 0 | I9: =G9-H9 -> 8 | J9: 0 | K9: =IF(F9="Done",J9-G9,"")
B10: 2.03 | C10: PB06 | D10: Build supported static dependency graph | E10: Pham Phan Hoang Huy | F10: Not started | G10: 16 | H10: =SUM(L10:Z10) -> 0 | I10: =G10-H10 -> 16 | J10: 0 | K10: =IF(F10="Done",J10-G10,"")
B11: 2.04 | C11: PB06 | D11: Traverse reverse-reachable potential impact and cycles | E11: Pham Phan Hoang Huy | F11: Not started | G11: 12 | H11: =SUM(L11:Z11) -> 0 | I11: =G11-H11 -> 12 | J11: 0 | K11: =IF(F11="Done",J11-G11,"")
B12: 2.05 | C12: PB06 | D12: Persist dependency paths and source evidence | E12: Nguyen Tan Huy | F12: Not started | G12: 8 | H12: =SUM(L12:Z12) -> 0 | I12: =G12-H12 -> 8 | J12: 0 | K12: =IF(F12="Done",J12-G12,"")
B13: 2.06 | C13: PB07 | D13: Explain potential impact and inspect individual evidence items | E13: Nguyen Tan Huy | F13: Not started | G13: 12 | H13: =SUM(L13:Z13) -> 0 | I13: =G13-H13 -> 12 | J13: 0 | K13: =IF(F13="Done",J13-G13,"")
B14: 2.07 | C14: PB08 | D14: Order review starting points deterministically | E14: Dang Dai Viet | F14: Not started | G14: 8 | H14: =SUM(L14:Z14) -> 0 | I14: =G14-H14 -> 8 | J14: 0 | K14: =IF(F14="Done",J14-G14,"")
B15: 2.08 | C15: PB09 | D15: Discover existing target tests in isolation | E15: Tran Hung Khanh | F15: Not started | G15: 12 | H15: =SUM(L15:Z15) -> 0 | I15: =G15-H15 -> 12 | J15: 0 | K15: =IF(F15="Done",J15-G15,"")
B16: 2.09 | C16: PB09 | D16: Distinguish empty, incomplete and failed discovery | E16: Tran Hung Khanh | F16: Not started | G16: 6 | H16: =SUM(L16:Z16) -> 0 | I16: =G16-H16 -> 6 | J16: 0 | K16: =IF(F16="Done",J16-G16,"")
B17: 2.10 | C17: PB19 | D17: Index permitted source, tests and documentation by snapshot | E17: Pham Phan Hoang Huy | F17: Not started | G17: 16 | H17: =SUM(L17:Z17) -> 0 | I17: =G17-H17 -> 16 | J17: 0 | K17: =IF(F17="Done",J17-G17,"")
B18: 2.11 | C18: PB20 | D18: Retrieve context from diff and candidate components | E18: Pham Phan Hoang Huy | F18: Not started | G18: 12 | H18: =SUM(L18:Z18) -> 0 | I18: =G18-H18 -> 12 | J18: 0 | K18: =IF(F18="Done",J18-G18,"")
B19: 2.12 | C19: PB20 | D19: Rank, deduplicate and verify retrieval metadata | E19: Dang Dai Viet | F19: Not started | G19: 8 | H19: =SUM(L19:Z19) -> 0 | I19: =G19-H19 -> 8 | J19: 0 | K19: =IF(F19="Done",J19-G19,"")
... B27: 2.20 | C27: PB04/06/09/19/20 | D27: Establish PostgreSQL persistence foundation | E27: Nguyen Tan Huy | F27: Not started | G27: 24 | H27: =SUM(L27:Z27) -> 0 | I27: =G27-H27 -> 24 | J27: 0 | K27: =IF(F27="Done",J27-G27,"")
F38: Total | G38: =SUM(G8:G27) -> 232 | H38: =SUM(H8:H27) -> 0 | I38: =SUM(I8:I27) -> 232 | J38: =SUM(J8:J27) -> 0 | K38: =IF(COUNTIF(F8:F27,"Done")=COUNTA(B8:B27),J38-G38,"") | L38: =SUM(L8:L27) -> 0 | M38: =SUM(M8:M27) -> 0 | N38: =SUM(N8:N27) -> 0 | O38: =SUM(O8:O27) -> 0 | P38: =SUM(P8:P27) -> 0 | Q38: =SUM(Q8:Q27) -> 0 | R38: =SUM(R8:R27) -> 0 | S38: =SUM(S8:S27) -> 0 | ... Z38: =SUM(Z8:Z27) -> 0
F39: Burn down | L39: =G38-L38 -> 232 | M39: =L39-M38 -> 232 | N39: =M39-N38 -> 232 | O39: =N39-O38 -> 232 | P39: =O39-P38 -> 232 | Q39: =P39-Q38 -> 232 | R39: =Q39-R38 -> 232 | S39: =R39-S38 -> 232 | T39: =S39-T38 -> 232 | ... Z39: =Y39-Z38 -> 232
F40: Burn up | L40: =L38 -> 0 | M40: =L40+M38 -> 0 | N40: =M40+N38 -> 0 | O40: =N40+O38 -> 0 | P40: =O40+P38 -> 0 | Q40: =P40+Q38 -> 0 | R40: =Q40+R38 -> 0 | S40: =R40+S38 -> 0 | T40: =S40+T38 -> 0 | ... Z40: =Y40+Z38 -> 0
J44: Worked hours/Day | L44: 1 | M44: 2 | N44: 3 | O44: 4 | P44: 5 | Q44: 6 | R44: 7 | S44: 8 | T44: 9 | U44: 10 | V44: 11 | W44: 12 | X44: 13 | Y44: 14 | Z44: 15 | AA44: Total hours
J45: Nguyen Tan Huy | AA45: =SUM(L45:Z45) -> 0
J46: Do Ha An | AA46: =SUM(L46:Z46) -> 0
J47: Pham Phan Hoang Huy | AA47: =SUM(L47:Z47) -> 0
J48: Tran Hung Khanh | AA48: =SUM(L48:Z48) -> 0
J49: Dang Dai Viet | AA49: =SUM(L49:Z49) -> 0
AA50: =SUM(AA45:AA49) -> 0
J51: Update actual worked hours per team member each day. Keep effort logs separate from planned task estimates.
B53: Sprint 2 task briefs (proposed scope and acceptance criteria) | C53: Sprint 2 task briefs (proposed scope and acceptance criteria) | D53: Sprint 2 task briefs (proposed scope and acceptance criteria) | E53: Sprint 2 task briefs (proposed scope and acceptance criteria) | F53: Sprint 2 task briefs (proposed scope and acceptance criteria) | G53: Sprint 2 task briefs (proposed scope and acceptance criteria) | H53: Sprint 2 task briefs (proposed scope and acceptance criteria) | I53: Sprint 2 task briefs (proposed scope and acceptance criteria) | J53: Sprint 2 task briefs (proposed scope and acceptance criteria) | K53: Sprint 2 task briefs (proposed scope and acceptance criteria)
B54: All tasks below are planned, not accepted results. Original IDs/PB links are retained; wording makes identity, isolation and limitations explicit. | C54: All tasks below are planned, not accepted results. Original IDs/PB links are retained; wording makes identity, isolation and limitations explicit. | D54: All tasks below are planned, not accepted results. Original IDs/PB links are retained; wording makes identity, isolation and limitations explicit. | E54: All tasks below are planned, not accepted results. Original IDs/PB links are retained; wording makes identity, isolation and limitations explicit. | F54: All tasks below are planned, not accepted results. Original IDs/PB links are retained; wording makes identity, isolation and limitations explicit. | G54: All tasks below are planned, not accepted results. Original IDs/PB links are retained; wording makes identity, isolation and limitations explicit. | H54: All tasks below are planned, not accepted results. Original IDs/PB links are retained; wording makes identity, isolation and limitations explicit. | I54: All tasks below are planned, not accepted results. Original IDs/PB links are retained; wording makes identity, isolation and limitations explicit. | J54: All tasks below are planned, not accepted results. Original IDs/PB links are retained; wording makes identity, isolation and limitations explicit. | K54: All tasks below are planned, not accepted results. Original IDs/PB links are retained; wording makes identity, isolation and limitations explicit.
B55: 2.01 Changed-component records at base/target revisions | C55: 2.01 Changed-component records at base/target revisions | D55: 2.01 Changed-component records at base/target revisions | E55: 2.01 Changed-component records at base/target revisions | F55: 2.01 Changed-component records at base/target revisions | G55: 2.01 Changed-component records at base/target revisions | H55: 2.01 Changed-component records at base/target revisions | I55: 2.01 Changed-component records at base/target revisions | J55: 2.01 Changed-component records at base/target revisions | K55: 2.01 Changed-component records at base/target revisions
B56: Dependencies | C56: Dependencies | D56: 2.14 contract; 2.15 snapshot | E56: 2.14 contract; 2.15 snapshot | F56: 2.14 contract; 2.15 snapshot | G56: 2.14 contract; 2.15 snapshot | H56: 2.14 contract; 2.15 snapshot | I56: 2.14 contract; 2.15 snapshot | J56: 2.14 contract; 2.15 snapshot | K56: 2.14 contract; 2.15 snapshot
B57: Acceptance criteria | C57: Acceptance criteria | D57: Handle add/modify/delete/rename with previous path; distinguish file/module/class/function granularity. Every location resolves at its declared base or target commit. Unsupported syntax is partial, not no-impact. | E57: Handle add/modify/delete/rename with previous path; distinguish file/module/class/function granularity. Every location resolves at its declared base or target commit. Unsupported syntax is partial, not no-impact. | F57: Handle add/modify/delete/rename with previous path; distinguish file/module/class/function granularity. Every location resolves at its declared base or target commit. Unsupported syntax is partial, not no-impact. | G57: Handle add/modify/delete/rename with previous path; distinguish file/module/class/function granularity. Every location resolves at its declared base or target commit. Unsupported syntax is partial, not no-impact. | H57: Handle add/modify/delete/rename with previous path; distinguish file/module/class/function granularity. Every location resolves at its declared base or target commit. Unsupported syntax is partial, not no-impact. | I57: Handle add/modify/delete/rename with previous path; distinguish file/module/class/function granularity. Every location resolves at its declared base or target commit. Unsupported syntax is partial, not no-impact. | J57: Handle add/modify/delete/rename with previous path; distinguish file/module/class/function granularity. Every location resolves at its declared base or target commit. Unsupported syntax is partial, not no-impact. | K57: Handle add/modify/delete/rename with previous path; distinguish file/module/class/function granularity. Every location resolves at its declared base or target commit. Unsupported syntax is partial, not no-impact.
B58: Verification planned | C58: Verification planned | D58: Fixtures with independently expected changes and immutable Git blobs; include deletion, rename and dirty-tree isolation. | E58: Fixtures with independently expected changes and immutable Git blobs; include deletion, rename and dirty-tree isolation. | F58: Fixtures with independently expected changes and immutable Git blobs; include deletion, rename and dirty-tree isolation. | G58: Fixtures with independently expected changes and immutable Git blobs; include deletion, rename and dirty-tree isolation. | H58: Fixtures with independently expected changes and immutable Git blobs; include deletion, rename and dirty-tree isolation. | I58: Fixtures with independently expected changes and immutable Git blobs; include deletion, rename and dirty-tree isolation. | J58: Fixtures with independently expected changes and immutable Git blobs; include deletion, rename and dirty-tree isolation. | K58: Fixtures with independently expected changes and immutable Git blobs; include deletion, rename and dirty-tree isolation.
B59: Traceability / review | C59: Traceability / review | D59: PB05. Reviewer proposed: pending. Allocation: Do Ha An 20h. | E59: PB05. Reviewer proposed: pending. Allocation: Do Ha An 20h. | F59: PB05. Reviewer proposed: pending. Allocation: Do Ha An 20h. | G59: PB05. Reviewer proposed: pending. Allocation: Do Ha An 20h. | H59: PB05. Reviewer proposed: pending. Allocation: Do Ha An 20h. | I59: PB05. Reviewer proposed: pending. Allocation: Do Ha An 20h. | J59: PB05. Reviewer proposed: pending. Allocation: Do Ha An 20h. | K59: PB05. Reviewer proposed: pending. Allocation: Do Ha An 20h.
B61: 2.02 Reviewed expected locations and mismatch record | C61: 2.02 Reviewed expected locations and mismatch record | D61: 2.02 Reviewed expected locations and mismatch record | E61: 2.02 Reviewed expected locations and mismatch record | F61: 2.02 Reviewed expected locations and mismatch record | G61: 2.02 Reviewed expected locations and mismatch record | H61: 2.02 Reviewed expected locations and mismatch record | I61: 2.02 Reviewed expected locations and mismatch record | J61: 2.02 Reviewed expected locations and mismatch record | K61: 2.02 Reviewed expected locations and mismatch record
B62: Dependencies | C62: Dependencies | D62: 2.01 output; 2.14 contract | E62: 2.01 output; 2.14 contract | F62: 2.01 output; 2.14 contract | G62: 2.01 output; 2.14 contract | H62: 2.01 output; 2.14 contract | I62: 2.01 output; 2.14 contract | J62: 2.01 output; 2.14 contract | K62: 2.01 output; 2.14 contract
B63: Acceptance criteria | C63: Acceptance criteria | D63: Compare output with independently prepared expected components and source ranges. Reject wrong commit/path/span; record unresolved labels and disagreements. Dependency reachability is not ground truth. | E63: Compare output with independently prepared expected components and source ranges. Reject wrong commit/path/span; record unresolved labels and disagreements. Dependency reachability is not ground truth. | F63: Compare output with independently prepared expected components and source ranges. Reject wrong commit/path/span; record unresolved labels and disagreements. Dependency reachability is not ground truth. | G63: Compare output with independently prepared expected components and source ranges. Reject wrong commit/path/span; record unresolved labels and disagreements. Dependency reachability is not ground truth. | H63: Compare output with independently prepared expected components and source ranges. Reject wrong commit/path/span; record unresolved labels and disagreements. Dependency reachability is not ground truth. | I63: Compare output with independently prepared expected components and source ranges. Reject wrong commit/path/span; record unresolved labels and disagreements. Dependency reachability is not ground truth. | J63: Compare output with independently prepared expected components and source ranges. Reject wrong commit/path/span; record unresolved labels and disagreements. Dependency reachability is not ground truth. | K63: Compare output with independently prepared expected components and source ranges. Reject wrong commit/path/span; record unresolved labels and disagreements. Dependency reachability is not ground truth.
B64: Verification planned | C64: Verification planned | D64: Positive and wrong-location cases; retain fixture revisions, expected records and mismatch evidence. | E64: Positive and wrong-location cases; retain fixture revisions, expected records and mismatch evidence. | F64: Positive and wrong-location cases; retain fixture revisions, expected records and mismatch evidence. | G64: Positive and wrong-location cases; retain fixture revisions, expected records and mismatch evidence. | H64: Positive and wrong-location cases; retain fixture revisions, expected records and mismatch evidence. | I64: Positive and wrong-location cases; retain fixture revisions, expected records and mismatch evidence. | J64: Positive and wrong-location cases; retain fixture revisions, expected records and mismatch evidence. | K64: Positive and wrong-location cases; retain fixture revisions, expected records and mismatch evidence.
...

Sheet Sprint 2 Reports
B5: Sprint 2 Reports & Dashboards
B7: Sprint goal: Change impact + dependency analysis + RAG retrieval core
B8: Planning revision: proposed task scope; results and review acceptance remain pending. | C8: Planning revision: proposed task scope; results and review acceptance remain pending. | D8: Planning revision: proposed task scope; results and review acceptance remain pending. | E8: Planning revision: proposed task scope; results and review acceptance remain pending. | F8: Planning revision: proposed task scope; results and review acceptance remain pending. | G8: Planning revision: proposed task scope; results and review acceptance remain pending. | H8: Planning revision: proposed task scope; results and review acceptance remain pending. | I8: Planning revision: proposed task scope; results and review acceptance remain pending. | J8: Planning revision: proposed task scope; results and review acceptance remain pending. | L8: Planning revision: proposed task scope; results and review acceptance remain pending. | M8: Planning revision: proposed task scope; results and review acceptance remain pending. | N8: Planning revision: proposed task scope; results and review acceptance remain pending. | O8: Planning revision: proposed task scope; results and review acceptance remain pending. | P8: Planning revision: proposed task scope; results and review acceptance remain pending. | Q8: Planning revision: proposed task scope; results and review acceptance remain pending. | R8: Planning revision: proposed task scope; results and review acceptance remain pending. | S8: Planning revision: proposed task scope; results and review acceptance remain pending. | T8: Planning revision: proposed task scope; results and review acceptance remain pending. | U8: Planning revision: proposed task scope; results and review acceptance remain pending. | V8: Planning revision: proposed task scope; results and review acceptance remain pending. | W8: Planning revision: proposed task scope; results and review acceptance remain pending. | X8: Planning revision: proposed task scope; results and review acceptance remain pending. | Y8: Planning revision: proposed task scope; results and review acceptance remain pending. | Z8: Planning revision: proposed task scope; results and review acceptance remain pending.
B10: Sprint 2 plan and decisions | C10: Sprint 2 plan and decisions | D10: Sprint 2 plan and decisions | E10: Sprint 2 plan and decisions | F10: Sprint 2 plan and decisions | G10: Sprint 2 plan and decisions | H10: Sprint 2 plan and decisions | I10: Sprint 2 plan and decisions | J10: Sprint 2 plan and decisions | K10: Sprint 2 plan and decisions | L10: Sprint 2 plan and decisions | M10: Sprint 2 plan and decisions | N10: Sprint 2 plan and decisions | O10: Sprint 2 plan and decisions | P10: Sprint 2 plan and decisions | Q10: Sprint 2 plan and decisions | R10: Sprint 2 plan and decisions | S10: Sprint 2 plan and decisions | T10: Sprint 2 plan and decisions | U10: Sprint 2 plan and decisions | V10: Sprint 2 plan and decisions | W10: Sprint 2 plan and decisions | X10: Sprint 2 plan and decisions | Y10: Sprint 2 plan and decisions | Z10: Sprint 2 plan and decisions
B11: Database decision | C11: Database decision | D11: Database decision | E11: PostgreSQL accepted by user on 2026-10-31. Python/FastAPI remains. ORM/driver, migration tool and minimum schema slice: pending. | F11: PostgreSQL accepted by user on 2026-10-31. Python/FastAPI remains. ORM/driver, migration tool and minimum schema slice: pending. | G11: PostgreSQL accepted by user on 2026-10-31. Python/FastAPI remains. ORM/driver, migration tool and minimum schema slice: pending. | H11: PostgreSQL accepted by user on 2026-10-31. Python/FastAPI remains. ORM/driver, migration tool and minimum schema slice: pending. | I11: PostgreSQL accepted by user on 2026-10-31. Python/FastAPI remains. ORM/driver, migration tool and minimum schema slice: pending. | J11: PostgreSQL accepted by user on 2026-10-31. Python/FastAPI remains. ORM/driver, migration tool and minimum schema slice: pending. | K11: PostgreSQL accepted by user on 2026-10-31. Python/FastAPI remains. ORM/driver, migration tool and minimum schema slice: pending. | L11: PostgreSQL accepted by user on 2026-10-31. Python/FastAPI remains. ORM/driver, migration tool and minimum schema slice: pending. | M11: PostgreSQL accepted by user on 2026-10-31. Python/FastAPI remains. ORM/driver, migration tool and minimum schema slice: pending. | N11: PostgreSQL accepted by user on 2026-10-31. Python/FastAPI remains. ORM/driver, migration tool and minimum schema slice: pending. | O11: PostgreSQL accepted by user on 2026-10-31. Python/FastAPI remains. ORM/driver, migration tool and minimum schema slice: pending. | P11: PostgreSQL accepted by user on 2026-10-31. Python/FastAPI remains. ORM/driver, migration tool and minimum schema slice: pending. | Q11: PostgreSQL accepted by user on 2026-10-31. Python/FastAPI remains. ORM/driver, migration tool and minimum schema slice: pending. | R11: PostgreSQL accepted by user on 2026-10-31. Python/FastAPI remains. ORM/driver, migration tool and minimum schema slice: pending. | S11: PostgreSQL accepted by user on 2026-10-31. Python/FastAPI remains. ORM/driver, migration tool and minimum schema slice: pending. | T11: PostgreSQL accepted by user on 2026-10-31. Python/FastAPI remains. ORM/driver, migration tool and minimum schema slice: pending. | U11: PostgreSQL accepted by user on 2026-10-31. Python/FastAPI remains. ORM/driver, migration tool and minimum schema slice: pending. | V11: PostgreSQL accepted by user on 2026-10-31. Python/FastAPI remains. ORM/driver, migration tool and minimum schema slice: pending. | W11: PostgreSQL accepted by user on 2026-10-31. Python/FastAPI remains. ORM/driver, migration tool and minimum schema slice: pending. | X11: PostgreSQL accepted by user on 2026-10-31. Python/FastAPI remains. ORM/driver, migration tool and minimum schema slice: pending. | Y11: PostgreSQL accepted by user on 2026-10-31. Python/FastAPI remains. ORM/driver, migration tool and minimum schema slice: pending. | Z11: PostgreSQL accepted by user on 2026-10-31. Python/FastAPI remains. ORM/driver, migration tool and minimum schema slice: pending.
B12: Goal | C12: Goal | D12: Goal | E12: Authorized Python/pytest repo with frozen base/target SHAs: changed components, potential impact paths, evidence, target inventory, test mapping and retrieved context. | F12: Authorized Python/pytest repo with frozen base/target SHAs: changed components, potential impact paths, evidence, target inventory, test mapping and retrieved context. | G12: Authorized Python/pytest repo with frozen base/target SHAs: changed components, potential impact paths, evidence, target inventory, test mapping and retrieved context. | H12: Authorized Python/pytest repo with frozen base/target SHAs: changed components, potential impact paths, evidence, target inventory, test mapping and retrieved context. | I12: Authorized Python/pytest repo with frozen base/target SHAs: changed components, potential impact paths, evidence, target inventory, test mapping and retrieved context. | J12: Authorized Python/pytest repo with frozen base/target SHAs: changed components, potential impact paths, evidence, target inventory, test mapping and retrieved context. | K12: Authorized Python/pytest repo with frozen base/target SHAs: changed components, potential impact paths, evidence, target inventory, test mapping and retrieved context. | L12: Authorized Python/pytest repo with frozen base/target SHAs: changed components, potential impact paths, evidence, target inventory, test mapping and retrieved context. | M12: Authorized Python/pytest repo with frozen base/target SHAs: changed components, potential impact paths, evidence, target inventory, test mapping and retrieved context. | N12: Authorized Python/pytest repo with frozen base/target SHAs: changed components, potential impact paths, evidence, target inventory, test mapping and retrieved context. | O12: Authorized Python/pytest repo with frozen base/target SHAs: changed components, potential impact paths, evidence, target inventory, test mapping and retrieved context. | P12: Authorized Python/pytest repo with frozen base/target SHAs: changed components, potential impact paths, evidence, target inventory, test mapping and retrieved context. | Q12: Authorized Python/pytest repo with frozen base/target SHAs: changed components, potential impact paths, evidence, target inventory, test mapping and retrieved context. | R12: Authorized Python/pytest repo with frozen base/target SHAs: changed components, potential impact paths, evidence, target inventory, test mapping and retrieved context. | S12: Authorized Python/pytest repo with frozen base/target SHAs: changed components, potential impact paths, evidence, target inventory, test mapping and retrieved context. | T12: Authorized Python/pytest repo with frozen base/target SHAs: changed components, potential impact paths, evidence, target inventory, test mapping and retrieved context. | U12: Authorized Python/pytest repo with frozen base/target SHAs: changed components, potential impact paths, evidence, target inventory, test mapping and retrieved context. | V12: Authorized Python/pytest repo with frozen base/target SHAs: changed components, potential impact paths, evidence, target inventory, test mapping and retrieved context. | W12: Authorized Python/pytest repo with frozen base/target SHAs: changed components, potential impact paths, evidence, target inventory, test mapping and retrieved context. | X12: Authorized Python/pytest repo with frozen base/target SHAs: changed components, potential impact paths, evidence, target inventory, test mapping and retrieved context. | Y12: Authorized Python/pytest repo with frozen base/target SHAs: changed components, potential impact paths, evidence, target inventory, test mapping and retrieved context. | Z12: Authorized Python/pytest repo with frozen base/target SHAs: changed components, potential impact paths, evidence, target inventory, test mapping and retrieved context.
B13: Planned task hours | C13: Planned task hours | D13: Planned task hours | E13: ='Sprint 2 Backlog'!G38 -> 232
B14: Proposed reserve | C14: Proposed reserve | D14: Proposed reserve | E14: ='Sprint 2 Backlog'!K192 -> 32
B15: Resource need | C15: Resource need | D15: Resource need | E15: ='Sprint 2 Backlog'!K193 -> 264
B16: Actual capacity | C16: Actual capacity | D16: Actual capacity | E16: Pending current member availability/commitment. Historical Project Plan assumes 300h per sprint; it does not confirm availability for this revised plan. | F16: Pending current member availability/commitment. Historical Project Plan assumes 300h per sprint; it does not confirm availability for this revised plan. | G16: Pending current member availability/commitment. Historical Project Plan assumes 300h per sprint; it does not confirm availability for this revised plan. | H16: Pending current member availability/commitment. Historical Project Plan assumes 300h per sprint; it does not confirm availability for this revised plan. | I16: Pending current member availability/commitment. Historical Project Plan assumes 300h per sprint; it does not confirm availability for this revised plan. | J16: Pending current member availability/commitment. Historical Project Plan assumes 300h per sprint; it does not confirm availability for this revised plan. | K16: Pending current member availability/commitment. Historical Project Plan assumes 300h per sprint; it does not confirm availability for this revised plan. | L16: Pending current member availability/commitment. Historical Project Plan assumes 300h per sprint; it does not confirm availability for this revised plan. | M16: Pending current member availability/commitment. Historical Project Plan assumes 300h per sprint; it does not confirm availability for this revised plan. | N16: Pending current member availability/commitment. Historical Project Plan assumes 300h per sprint; it does not confirm availability for this revised plan. | O16: Pending current member availability/commitment. Historical Project Plan assumes 300h per sprint; it does not confirm availability for this revised plan. | P16: Pending current member availability/commitment. Historical Project Plan assumes 300h per sprint; it does not confirm availability for this revised plan. | Q16: Pending current member availability/commitment. Historical Project Plan assumes 300h per sprint; it does not confirm availability for this revised plan. | R16: Pending current member availability/commitment. Historical Project Plan assumes 300h per sprint; it does not confirm availability for this revised plan. | S16: Pending current member availability/commitment. Historical Project Plan assumes 300h per sprint; it does not confirm availability for this revised plan. | T16: Pending current member availability/commitment. Historical Project Plan assumes 300h per sprint; it does not confirm availability for this revised plan. | U16: Pending current member availability/commitment. Historical Project Plan assumes 300h per sprint; it does not confirm availability for this revised plan. | V16: Pending current member availability/commitment. Historical Project Plan assumes 300h per sprint; it does not confirm availability for this revised plan. | W16: Pending current member availability/commitment. Historical Project Plan assumes 300h per sprint; it does not confirm availability for this revised plan. | X16: Pending current member availability/commitment. Historical Project Plan assumes 300h per sprint; it does not confirm availability for this revised plan. | Y16: Pending current member availability/commitment. Historical Project Plan assumes 300h per sprint; it does not confirm availability for this revised plan. | Z16: Pending current member availability/commitment. Historical Project Plan assumes 300h per sprint; it does not confirm availability for this revised plan.
B17: Results / acceptance | C17: Results / acceptance | D17: Results / acceptance | E17: Not measured / pending. No implementation, benchmark accuracy, human approval or actual effort is asserted by this planning revision. | F17: Not measured / pending. No implementation, benchmark accuracy, human approval or actual effort is asserted by this planning revision. | G17: Not measured / pending. No implementation, benchmark accuracy, human approval or actual effort is asserted by this planning revision. | H17: Not measured / pending. No implementation, benchmark accuracy, human approval or actual effort is asserted by this planning revision. | I17: Not measured / pending. No implementation, benchmark accuracy, human approval or actual effort is asserted by this planning revision. | J17: Not measured / pending. No implementation, benchmark accuracy, human approval or actual effort is asserted by this planning revision. | K17: Not measured / pending. No implementation, benchmark accuracy, human approval or actual effort is asserted by this planning revision. | L17: Not measured / pending. No implementation, benchmark accuracy, human approval or actual effort is asserted by this planning revision. | M17: Not measured / pending. No implementation, benchmark accuracy, human approval or actual effort is asserted by this planning revision. | N17: Not measured / pending. No implementation, benchmark accuracy, human approval or actual effort is asserted by this planning revision. | O17: Not measured / pending. No implementation, benchmark accuracy, human approval or actual effort is asserted by this planning revision. | P17: Not measured / pending. No implementation, benchmark accuracy, human approval or actual effort is asserted by this planning revision. | Q17: Not measured / pending. No implementation, benchmark accuracy, human approval or actual effort is asserted by this planning revision. | R17: Not measured / pending. No implementation, benchmark accuracy, human approval or actual effort is asserted by this planning revision. | S17: Not measured / pending. No implementation, benchmark accuracy, human approval or actual effort is asserted by this planning revision. | T17: Not measured / pending. No implementation, benchmark accuracy, human approval or actual effort is asserted by this planning revision. | U17: Not measured / pending. No implementation, benchmark accuracy, human approval or actual effort is asserted by this planning revision. | V17: Not measured / pending. No implementation, benchmark accuracy, human approval or actual effort is asserted by this planning revision. | W17: Not measured / pending. No implementation, benchmark accuracy, human approval or actual effort is asserted by this planning revision. | X17: Not measured / pending. No implementation, benchmark accuracy, human approval or actual effort is asserted by this planning revision. | Y17: Not measured / pending. No implementation, benchmark accuracy, human approval or actual effort is asserted by this planning revision. | Z17: Not measured / pending. No implementation, benchmark accuracy, human approval or actual effort is asserted by this planning revision.
B18: Baseline reconciliation | C18: Baseline reconciliation | D18: Baseline reconciliation | E18: Backlog original 13 tasks = 150h; Main previously 184h. Revised task plan = 232h. Project Plan 250h = PB-level 195h + 55h overhead; do not add these estimates together. | F18: Backlog original 13 tasks = 150h; Main previously 184h. Revised task plan = 232h. Project Plan 250h = PB-level 195h + 55h overhead; do not add these estimates together. | G18: Backlog original 13 tasks = 150h; Main previously 184h. Revised task plan = 232h. Project Plan 250h = PB-level 195h + 55h overhead; do not add these estimates together. | H18: Backlog original 13 tasks = 150h; Main previously 184h. Revised task plan = 232h. Project Plan 250h = PB-level 195h + 55h overhead; do not add these estimates together. | I18: Backlog original 13 tasks = 150h; Main previously 184h. Revised task plan = 232h. Project Plan 250h = PB-level 195h + 55h overhead; do not add these estimates together. | J18: Backlog original 13 tasks = 150h; Main previously 184h. Revised task plan = 232h. Project Plan 250h = PB-level 195h + 55h overhead; do not add these estimates together. | K18: Backlog original 13 tasks = 150h; Main previously 184h. Revised task plan = 232h. Project Plan 250h = PB-level 195h + 55h overhead; do not add these estimates together. | L18: Backlog original 13 tasks = 150h; Main previously 184h. Revised task plan = 232h. Project Plan 250h = PB-level 195h + 55h overhead; do not add these estimates together. | M18: Backlog original 13 tasks = 150h; Main previously 184h. Revised task plan = 232h. Project Plan 250h = PB-level 195h + 55h overhead; do not add these estimates together. | N18: Backlog original 13 tasks = 150h; Main previously 184h. Revised task plan = 232h. Project Plan 250h = PB-level 195h + 55h overhead; do not add these estimates together. | O18: Backlog original 13 tasks = 150h; Main previously 184h. Revised task plan = 232h. Project Plan 250h = PB-level 195h + 55h overhead; do not add these estimates together. | P18: Backlog original 13 tasks = 150h; Main previously 184h. Revised task plan = 232h. Project Plan 250h = PB-level 195h + 55h overhead; do not add these estimates together. | Q18: Backlog original 13 tasks = 150h; Main previously 184h. Revised task plan = 232h. Project Plan 250h = PB-level 195h + 55h overhead; do not add these estimates together. | R18: Backlog original 13 tasks = 150h; Main previously 184h. Revised task plan = 232h. Project Plan 250h = PB-level 195h + 55h overhead; do not add these estimates together. | S18: Backlog original 13 tasks = 150h; Main previously 184h. Revised task plan = 232h. Project Plan 250h = PB-level 195h + 55h overhead; do not add these estimates together. | T18: Backlog original 13 tasks = 150h; Main previously 184h. Revised task plan = 232h. Project Plan 250h = PB-level 195h + 55h overhead; do not add these estimates together. | U18: Backlog original 13 tasks = 150h; Main previously 184h. Revised task plan = 232h. Project Plan 250h = PB-level 195h + 55h overhead; do not add these estimates together. | V18: Backlog original 13 tasks = 150h; Main previously 184h. Revised task plan = 232h. Project Plan 250h = PB-level 195h + 55h overhead; do not add these estimates together. | W18: Backlog original 13 tasks = 150h; Main previously 184h. Revised task plan = 232h. Project Plan 250h = PB-level 195h + 55h overhead; do not add these estimates together. | X18: Backlog original 13 tasks = 150h; Main previously 184h. Revised task plan = 232h. Project Plan 250h = PB-level 195h + 55h overhead; do not add these estimates together. | Y18: Backlog original 13 tasks = 150h; Main previously 184h. Revised task plan = 232h. Project Plan 250h = PB-level 195h + 55h overhead; do not add these estimates together. | Z18: Backlog original 13 tasks = 150h; Main previously 184h. Revised task plan = 232h. Project Plan 250h = PB-level 195h + 55h overhead; do not add these estimates together.
B19: Dates | C19: Dates | D19: Dates | E19: Existing workbook dates/statuses retained. Use relative three-week sequencing; no new calendar start/end dates supplied. | F19: Existing workbook dates/statuses retained. Use relative three-week sequencing; no new calendar start/end dates supplied. | G19: Existing workbook dates/statuses retained. Use relative three-week sequencing; no new calendar start/end dates supplied. | H19: Existing workbook dates/statuses retained. Use relative three-week sequencing; no new calendar start/end dates supplied. | I19: Existing workbook dates/statuses retained. Use relative three-week sequencing; no new calendar start/end dates supplied. | J19: Existing workbook dates/statuses retained. Use relative three-week sequencing; no new calendar start/end dates supplied. | K19: Existing workbook dates/statuses retained. Use relative three-week sequencing; no new calendar start/end dates supplied. | L19: Existing workbook dates/statuses retained. Use relative three-week sequencing; no new calendar start/end dates supplied. | M19: Existing workbook dates/statuses retained. Use relative three-week sequencing; no new calendar start/end dates supplied. | N19: Existing workbook dates/statuses retained. Use relative three-week sequencing; no new calendar start/end dates supplied. | O19: Existing workbook dates/statuses retained. Use relative three-week sequencing; no new calendar start/end dates supplied. | P19: Existing workbook dates/statuses retained. Use relative three-week sequencing; no new calendar start/end dates supplied. | Q19: Existing workbook dates/statuses retained. Use relative three-week sequencing; no new calendar start/end dates supplied. | R19: Existing workbook dates/statuses retained. Use relative three-week sequencing; no new calendar start/end dates supplied. | S19: Existing workbook dates/statuses retained. Use relative three-week sequencing; no new calendar start/end dates supplied. | T19: Existing workbook dates/statuses retained. Use relative three-week sequencing; no new calendar start/end dates supplied. | U19: Existing workbook dates/statuses retained. Use relative three-week sequencing; no new calendar start/end dates supplied. | V19: Existing workbook dates/statuses retained. Use relative three-week sequencing; no new calendar start/end dates supplied. | W19: Existing workbook dates/statuses retained. Use relative three-week sequencing; no new calendar start/end dates supplied. | X19: Existing workbook dates/statuses retained. Use relative three-week sequencing; no new calendar start/end dates supplied. | Y19: Existing workbook dates/statuses retained. Use relative three-week sequencing; no new calendar start/end dates supplied. | Z19: Existing workbook dates/statuses retained. Use relative three-week sequencing; no new calendar start/end dates supplied.
B21: Dependencies and planned acceptance | C21: Dependencies and planned acceptance | D21: Dependencies and planned acceptance | E21: Dependencies and planned acceptance | F21: Dependencies and planned acceptance | G21: Dependencies and planned acceptance | H21: Dependencies and planned acceptance | I21: Dependencies and planned acceptance | J21: Dependencies and planned acceptance | K21: Dependencies and planned acceptance | L21: Dependencies and planned acceptance | M21: Dependencies and planned acceptance | N21: Dependencies and planned acceptance | O21: Dependencies and planned acceptance | P21: Dependencies and planned acceptance | Q21: Dependencies and planned acceptance | R21: Dependencies and planned acceptance | S21: Dependencies and planned acceptance | T21: Dependencies and planned acceptance | U21: Dependencies and planned acceptance | V21: Dependencies and planned acceptance | W21: Dependencies and planned acceptance | X21: Dependencies and planned acceptance | Y21: Dependencies and planned acceptance | Z21: Dependencies and planned acceptance
